<robot xmlns:xacro="http://www.ros.org/wiki/xacro">

  <!-- Wheel Link + Joint -->
  <xacro:macro name="wheel" params="locationprefix">

    <link name="${locationprefix}_wheel_link">
      <inertial>
        <origin xyz="-0.0016559 2.498E-05 -1.1185E-05" rpy="0 0 0" />
        <mass value="0.11363" />
        <inertia ixx="0.0049366" ixy="-9.2744E-07" ixz="2.0492E-07" iyy="0.002578" iyz="9.052E-08" izz="0.0025791" />
      </inertial>
      <visual>
        <origin xyz="0 0 0" rpy="0 0 0" />
        <geometry>
          <mesh filename="file://$(find swerve_robot_description)/meshes/${locationprefix}_wheel_link.dae" />
        </geometry>
      </visual>
      <collision>
        <origin xyz="0 0 0" rpy="0 0 0" />
        <geometry>
          <mesh filename="file://$(find swerve_robot_description)/meshes/${locationprefix}_wheel_link.dae" />
        </geometry>
      </collision>
    </link>

    <gazebo reference="${locationprefix}_wheel_link">
      <material>Gazebo/Black</material>
    </gazebo>

    <joint name="wheel_${locationprefix}_joint" type="continuous">
      <origin xyz="0.0 0.0 0.093" rpy="0 0 0" />
      <parent link="${locationprefix}_steering_link" />
      <child link="${locationprefix}_wheel_link" />
      <axis xyz="0 1 0" />
      <limit effort="1.0" velocity="27" />
    </joint>

  </xacro:macro>

</robot>
